Workbook

Sheet Guest List
A1: CONFIRMED GUESTS
A2: Paste your guest list below (one name per row)
A3: # | B3: Guest Name
A4: 1 | B4: Robb Topp
A5: 2 | B5: Marianne Chardon
A6: 3 | B6: Ronan Keohane
A7: 4 | B7: Sean Horan
A8: 5 | B8: Anthony Burke
A9: 6 | B9: Denise White
A10: 7 | B10: Bryan White
A11: 8 | B11: Ryan Crowley
A12: 9 | B12: Vahi Crowley
A13: 10 | B13: David Owens
A14: 11 | B14: Ivan Bogdanov
A15: 12 | B15: Stephen Hughes
... A30: 27 | B30: Jade Dally
A31: 28
A32: 29
A33: 30
A34: 31
A35: 32
A36: 33
A37: 34
A38: 35
A39: 36
A40: 37
A41: 38
A42: 39
... A53: 50

Sheet Race Card
A1: RACE CARD — Enter horse names the day before
A2: Fill in the horse names for each race below. These power the dropdown menus on the Picks & Scores tab.
A3: # | B3: The Chesham Stakes (14:30) | C3: The King George V Stakes (15:05) | D3: The Ribblesdale Stakes (15:40) | E3: The Gold Cup (16:15) | F3: The Britannia Stakes (16:50)
A4: 1 | B4: Aix La Chapelle | C4: Guildmaster | D4: Brilliant Star | E4: Al Nayyir | F4: Pathein
A5: 2 | B5: Celtic Charioteer | C5: Tierra Del Toro | D5: Composing | E5: Al Riffa | F5: Wise Prince
A6: 3 | B6: Nola Soul | C6: Cannes | D6: Dark Lucinda | E6: Caballo De Mar | F6: Organise
A7: 4 | B7: On Just Terms | C7: Birgham Dub | D7: Earth Shot | E7: Dubai Future | F7: Tales Of Wisdom
A8: 5 | B8: Pikachu | C8: Al Azd | D8: Gilded Prize | E8: Sweet William | F8: Hilitany
A9: 6 | B9: Revels | C9: Joulany | D9: Golden Orbit | E9: Trawlerman | F9: Flushing Meadows
A10: 7 | B10: Romanza | C10: Amora Queen | D10: Johanna Walsh | E10: Carmers | F10: Laureate Crown
A11: 8 | B11: South Dakota | C11: Atomic City | D11: Lady Roisia | E11: Furthur | F11: Conclave
A12: 9 | B12: Sword Salute | C12: Dial Me In | D12: Legacy Link | E12: Rahiebb | F12: New Connection
A13: 10 | B13: Sydney Carton | C13: Enceladus | D13: Maldives | E13: Scandinavia | F13: We're Goosers
A14: 11 | B14: Time For The Moon | C14: Believed | D14: Venetia | E14: Miss Alpilles | F14: Wechaad
A15: 12 | B15: Whispering Moon | C15: Into The Light | D15: Warriors Whisper | F15: Richie's Rocket
A16: 13 | B16: Aperoll | C16: Golden Knight | F16: Victory Tip
A17: 14 | B17: Bayside | C17: Waterford Castle | F17: Langstone
A18: 15 | B18: Sea Venture | C18: Genchev | F18: Charly
A19: 16 | C19: Arc Ole Ole | F19: Bobby McGee
A20: 17 | C20: Heyzoom | F20: Blue Courvoisier
A21: 18 | C21: Galilean Quality | F21: Noelan Star
A22: 19 | C22: Blue Hercules | F22: Intense Vision
A23: 20 | C23: Who's Lope | F23: Outback Heat
A24: 21 | C24: Charles Darnay | F24: St Anton
A25: 22 | C25: Bnaider | F25: Capall Rasa
A26: 23 | F26: Runman
A27: 24 | F27: New Monarch
A28: 25 | F28: Vincenzo Peruggia
A29: 26 | F29: Crest Of Fire
A30: 27 | F30: Moonfall
A31: 28 | F31: Lion Of Alba
A32: 29 | F32: Jamestown
A33: 30 | F33: Exclusive Code
A34: 31 | F34: Winding Stream
A35: 32 | F35: Synners Kid
A36: 33 | F36: Wild Thoughts

Sheet Race Results
A1: RACE RESULTS — Enter after each race
A2: SCORING: 1st = 10 pts | 2nd = 6 pts | 3rd = 4 pts | 4th = 3 pts | 5th = 2 pts | 6th = 1 pt
A3: Race | B3: 1st (10pts) | C3: 2nd (6pts) | D3: 3rd (4pts) | E3: 4th (3pts) | F3: 5th (2pts) | G3: 6th (1pt)
A4: The Chesham Stakes (14:30) | B4: Romanza | C4: Pikachu | D4: Sydney Carton | E4: Nola Soul | F4: Revels | G4: Bayside
A5: The King George V Stakes (15:05) | B5: Guildmaster | C5: Atomic City | D5: Arc Ole Ole | E5: Blue Hercules | F5: Who's Lope | G5: Charles Darnay
A6: The Ribblesdale Stakes (15:40) | B6: Maldives | C6: Earth Shot | D6: Brilliant Star | E6: Lady Roisia | F6: Venetia | G6: Golden Orbit
A7: The Gold Cup (16:15)
A8: The Britannia Stakes (16:50)
A11: Type or select the finishing horses after each race. Points calculate automatically.

Sheet Picks & Scores
A1: ASCOT LADIES DAY 2026 — TIPPING COMPETITION
A2: SCORING: 1st = 10 | 2nd = 6 | 3rd = 4 | 4th = 3 | 5th = 2 | 6th = 1 | Outside top 6 = 0
A3: # | B3: Guest Name | C3: Chesham Stakes Pick | D3: Pts | E3: King George V Pick | F3: Pts | G3: Ribblesdale Stakes Pick | H3: Pts | I3: Gold Cup Pick | J3: Pts | K3: Britannia Stakes Pick | L3: Pts | M3: TOTAL
A4: 1 | B4: Robb Topp | C4: Romanza | D4: =IF(C4="","",IF(UPPER(C4)=UPPER('Race Results'!B4),10,IF(UPPER(C4)=UPPER('Race Results'!C4),6,IF(UPPER(C4)=UPPER('Race Results'!D4),4,IF(UPPER(C4)=UPPER('Race Results'!E4),3,IF(UPPER(C4)=UPPER('Race Results'!F4),2,IF(UPPER(C4)=UPPER('Race Results'!G4),1,0))))))) -> 10 | E4: Atomic City | F4: =IF(E4="","",IF(UPPER(E4)=UPPER('Race Results'!B5),10,IF(UPPER(E4)=UPPER('Race Results'!C5),6,IF(UPPER(E4)=UPPER('Race Results'!D5),4,IF(UPPER(E4)=UPPER('Race Results'!E5),3,IF(UPPER(E4)=UPPER('Race Results'!F5),2,IF(UPPER(E4)=UPPER('Race Results'!G5),1,0))))))) -> 6 | G4: Maldives | H4: =IF(G4="","",IF(UPPER(G4)=UPPER('Race Results'!B6),10,IF(UPPER(G4)=UPPER('Race Results'!C6),6,IF(UPPER(G4)=UPPER('Race Results'!D6),4,IF(UPPER(G4)=UPPER('Race Results'!E6),3,IF(UPPER(G4)=UPPER('Race Results'!F6),2,IF(UPPER(G4)=UPPER('Race Results'!G6),1,0))))))) -> 10 | I4: Sweet William | J4: =IF(I4="","",IF(UPPER(I4)=UPPER('Race Results'!B7),10,IF(UPPER(I4)=UPPER('Race Results'!C7),6,IF(UPPER(I4)=UPPER('Race Results'!D7),4,IF(UPPER(I4)=UPPER('Race Results'!E7),3,IF(UPPER(I4)=UPPER('Race Results'!F7),2,IF(UPPER(I4)=UPPER('Race Results'!G7),1,0))))))) -> 0 | K4: Moonfall | L4: =IF(K4="","",IF(UPPER(K4)=UPPER('Race Results'!B8),10,IF(UPPER(K4)=UPPER('Race Results'!C8),6,IF(UPPER(K4)=UPPER('Race Results'!D8),4,IF(UPPER(K4)=UPPER('Race Results'!E8),3,IF(UPPER(K4)=UPPER('Race Results'!F8),2,IF(UPPER(K4)=UPPER('Race Results'!G8),1,0))))))) -> 0 | M4: =IF(COUNTA(D4,F4,H4,J4,L4)=0,"",SUM(D4,F4,H4,J4,L4)) -> 26
A5: 2 | B5: Marianne Chardon | C5: Pikachu | D5: =IF(C5="","",IF(UPPER(C5)=UPPER('Race Results'!B4),10,IF(UPPER(C5)=UPPER('Race Results'!C4),6,IF(UPPER(C5)=UPPER('Race Results'!D4),4,IF(UPPER(C5)=UPPER('Race Results'!E4),3,IF(UPPER(C5)=UPPER('Race Results'!F4),2,IF(UPPER(C5)=UPPER('Race Results'!G4),1,0))))))) -> 6 | E5: Guildmaster | F5: =IF(E5="","",IF(UPPER(E5)=UPPER('Race Results'!B5),10,IF(UPPER(E5)=UPPER('Race Results'!C5),6,IF(UPPER(E5)=UPPER('Race Results'!D5),4,IF(UPPER(E5)=UPPER('Race Results'!E5),3,IF(UPPER(E5)=UPPER('Race Results'!F5),2,IF(UPPER(E5)=UPPER('Race Results'!G5),1,0))))))) -> 10 | G5: Earth Shot | H5: =IF(G5="","",IF(UPPER(G5)=UPPER('Race Results'!B6),10,IF(UPPER(G5)=UPPER('Race Results'!C6),6,IF(UPPER(G5)=UPPER('Race Results'!D6),4,IF(UPPER(G5)=UPPER('Race Results'!E6),3,IF(UPPER(G5)=UPPER('Race Results'!F6),2,IF(UPPER(G5)=UPPER('Race Results'!G6),1,0))))))) -> 6 | I5: Trawlerman | J5: =IF(I5="","",IF(UPPER(I5)=UPPER('Race Results'!B7),10,IF(UPPER(I5)=UPPER('Race Results'!C7),6,IF(UPPER(I5)=UPPER('Race Results'!D7),4,IF(UPPER(I5)=UPPER('Race Results'!E7),3,IF(UPPER(I5)=UPPER('Race Results'!F7),2,IF(UPPER(I5)=UPPER('Race Results'!G7),1,0))))))) -> 0 | K5: Langstone | L5: =IF(K5="","",IF(UPPER(K5)=UPPER('Race Results'!B8),10,IF(UPPER(K5)=UPPER('Race Results'!C8),6,IF(UPPER(K5)=UPPER('Race Results'!D8),4,IF(UPPER(K5)=UPPER('Race Results'!E8),3,IF(UPPER(K5)=UPPER('Race Results'!F8),2,IF(UPPER(K5)=UPPER('Race Results'!G8),1,0))))))) -> 0 | M5: =IF(COUNTA(D5,F5,H5,J5,L5)=0,"",SUM(D5,F5,H5,J5,L5)) -> 22
A6: 3 | B6: Ronan Keohane | C6: Sydney Carton | D6: =IF(C6="","",IF(UPPER(C6)=UPPER('Race Results'!B4),10,IF(UPPER(C6)=UPPER('Race Results'!C4),6,IF(UPPER(C6)=UPPER('Race Results'!D4),4,IF(UPPER(C6)=UPPER('Race Results'!E4),3,IF(UPPER(C6)=UPPER('Race Results'!F4),2,IF(UPPER(C6)=UPPER('Race Results'!G4),1,0))))))) -> 4 | E6: Cannes | F6: =IF(E6="","",IF(UPPER(E6)=UPPER('Race Results'!B5),10,IF(UPPER(E6)=UPPER('Race Results'!C5),6,IF(UPPER(E6)=UPPER('Race Results'!D5),4,IF(UPPER(E6)=UPPER('Race Results'!E5),3,IF(UPPER(E6)=UPPER('Race Results'!F5),2,IF(UPPER(E6)=UPPER('Race Results'!G5),1,0))))))) -> 0 | G6: Brilliant Star | H6: =IF(G6="","",IF(UPPER(G6)=UPPER('Race Results'!B6),10,IF(UPPER(G6)=UPPER('Race Results'!C6),6,IF(UPPER(G6)=UPPER('Race Results'!D6),4,IF(UPPER(G6)=UPPER('Race Results'!E6),3,IF(UPPER(G6)=UPPER('Race Results'!F6),2,IF(UPPER(G6)=UPPER('Race Results'!G6),1,0))))))) -> 4 | I6: Al Riffa | J6: =IF(I6="","",IF(UPPER(I6)=UPPER('Race Results'!B7),10,IF(UPPER(I6)=UPPER('Race Results'!C7),6,IF(UPPER(I6)=UPPER('Race Results'!D7),4,IF(UPPER(I6)=UPPER('Race Results'!E7),3,IF(UPPER(I6)=UPPER('Race Results'!F7),2,IF(UPPER(I6)=UPPER('Race Results'!G7),1,0))))))) -> 0 | K6: Charly | L6: =IF(K6="","",IF(UPPER(K6)=UPPER('Race Results'!B8),10,IF(UPPER(K6)=UPPER('Race Results'!C8),6,IF(UPPER(K6)=UPPER('Race Results'!D8),4,IF(UPPER(K6)=UPPER('Race Results'!E8),3,IF(UPPER(K6)=UPPER('Race Results'!F8),2,IF(UPPER(K6)=UPPER('Race Results'!G8),1,0))))))) -> 0 | M6: =IF(COUNTA(D6,F6,H6,J6,L6)=0,"",SUM(D6,F6,H6,J6,L6)) -> 8
A7: 4 | B7: Sean Horan | C7: Romanza | D7: =IF(C7="","",IF(UPPER(C7)=UPPER('Race Results'!B4),10,IF(UPPER(C7)=UPPER('Race Results'!C4),6,IF(UPPER(C7)=UPPER('Race Results'!D4),4,IF(UPPER(C7)=UPPER('Race Results'!E4),3,IF(UPPER(C7)=UPPER('Race Results'!F4),2,IF(UPPER(C7)=UPPER('Race Results'!G4),1,0))))))) -> 10 | E7: Believed | F7: =IF(E7="","",IF(UPPER(E7)=UPPER('Race Results'!B5),10,IF(UPPER(E7)=UPPER('Race Results'!C5),6,IF(UPPER(E7)=UPPER('Race Results'!D5),4,IF(UPPER(E7)=UPPER('Race Results'!E5),3,IF(UPPER(E7)=UPPER('Race Results'!F5),2,IF(UPPER(E7)=UPPER('Race Results'!G5),1,0))))))) -> 0 | G7: Lady Roisia | H7: =IF(G7="","",IF(UPPER(G7)=UPPER('Race Results'!B6),10,IF(UPPER(G7)=UPPER('Race Results'!C6),6,IF(UPPER(G7)=UPPER('Race Results'!D6),4,IF(UPPER(G7)=UPPER('Race Results'!E6),3,IF(UPPER(G7)=UPPER('Race Results'!F6),2,IF(UPPER(G7)=UPPER('Race Results'!G6),1,0))))))) -> 3 | I7: Sweet William | J7: =IF(I7="","",IF(UPPER(I7)=UPPER('Race Results'!B7),10,IF(UPPER(I7)=UPPER('Race Results'!C7),6,IF(UPPER(I7)=UPPER('Race Results'!D7),4,IF(UPPER(I7)=UPPER('Race Results'!E7),3,IF(UPPER(I7)=UPPER('Race Results'!F7),2,IF(UPPER(I7)=UPPER('Race Results'!G7),1,0))))))) -> 0 | K7: New Monarch | L7: =IF(K7="","",IF(UPPER(K7)=UPPER('Race Results'!B8),10,IF(UPPER(K7)=UPPER('Race Results'!C8),6,IF(UPPER(K7)=UPPER('Race Results'!D8),4,IF(UPPER(K7)=UPPER('Race Results'!E8),3,IF(UPPER(K7)=UPPER('Race Results'!F8),2,IF(UPPER(K7)=UPPER('Race Results'!G8),1,0))))))) -> 0 | M7: =IF(COUNTA(D7,F7,H7,J7,L7)=0,"",SUM(D7,F7,H7,J7,L7)) -> 13
A8: 5 | B8: Anthony Burke | C8: Nola Soul | D8: =IF(C8="","",IF(UPPER(C8)=UPPER('Race Results'!B4),10,IF(UPPER(C8)=UPPER('Race Results'!C4),6,IF(UPPER(C8)=UPPER('Race Results'!D4),4,IF(UPPER(C8)=UPPER('Race Results'!E4),3,IF(UPPER(C8)=UPPER('Race Results'!F4),2,IF(UPPER(C8)=UPPER('Race Results'!G4),1,0))))))) -> 3 | E8: Atomic City | F8: =IF(E8="","",IF(UPPER(E8)=UPPER('Race Results'!B5),10,IF(UPPER(E8)=UPPER('Race Results'!C5),6,IF(UPPER(E8)=UPPER('Race Results'!D5),4,IF(UPPER(E8)=UPPER('Race Results'!E5),3,IF(UPPER(E8)=UPPER('Race Results'!F5),2,IF(UPPER(E8)=UPPER('Race Results'!G5),1,0))))))) -> 6 | G8: Maldives | H8: =IF(G8="","",IF(UPPER(G8)=UPPER('Race Results'!B6),10,IF(UPPER(G8)=UPPER('Race Results'!C6),6,IF(UPPER(G8)=UPPER('Race Results'!D6),4,IF(UPPER(G8)=UPPER('Race Results'!E6),3,IF(UPPER(G8)=UPPER('Race Results'!F6),2,IF(UPPER(G8)=UPPER('Race Results'!G6),1,0))))))) -> 10 | I8: Scandinavia | J8: =IF(I8="","",IF(UPPER(I8)=UPPER('Race Results'!B7),10,IF(UPPER(I8)=UPPER('Race Results'!C7),6,IF(UPPER(I8)=UPPER('Race Results'!D7),4,IF(UPPER(I8)=UPPER('Race Results'!E7),3,IF(UPPER(I8)=UPPER('Race Results'!F7),2,IF(UPPER(I8)=UPPER('Race Results'!G7),1,0))))))) -> 0 | K8: Wise Prince | L8: =IF(K8="","",IF(UPPER(K8)=UPPER('Race Results'!B8),10,IF(UPPER(K8)=UPPER('Race Results'!C8),6,IF(UPPER(K8)=UPPER('Race Results'!D8),4,IF(UPPER(K8)=UPPER('Race Results'!E8),3,IF(UPPER(K8)=UPPER('Race Results'!F8),2,IF(UPPER(K8)=UPPER('Race Results'!G8),1,0))))))) -> 0 | M8: =IF(COUNTA(D8,F8,H8,J8,L8)=0,"",SUM(D8,F8,H8,J8,L8)) -> 19
A9: 6 | B9: Denise White | C9: Revels | D9: =IF(C9="","",IF(UPPER(C9)=UPPER('Race Results'!B4),10,IF(UPPER(C9)=UPPER('Race Results'!C4),6,IF(UPPER(C9)=UPPER('Race Results'!D4),4,IF(UPPER(C9)=UPPER('Race Results'!E4),3,IF(UPPER(C9)=UPPER('Race Results'!F4),2,IF(UPPER(C9)=UPPER('Race Results'!G4),1,0))))))) -> 2 | E9: Heyzoom | F9: =IF(E9="","",IF(UPPER(E9)=UPPER('Race Results'!B5),10,IF(UPPER(E9)=UPPER('Race Results'!C5),6,IF(UPPER(E9)=UPPER('Race Results'!D5),4,IF(UPPER(E9)=UPPER('Race Results'!E5),3,IF(UPPER(E9)=UPPER('Race Results'!F5),2,IF(UPPER(E9)=UPPER('Race Results'!G5),1,0))))))) -> 0 | G9: Venetia | H9: =IF(G9="","",IF(UPPER(G9)=UPPER('Race Results'!B6),10,IF(UPPER(G9)=UPPER('Race Results'!C6),6,IF(UPPER(G9)=UPPER('Race Results'!D6),4,IF(UPPER(G9)=UPPER('Race Results'!E6),3,IF(UPPER(G9)=UPPER('Race Results'!F6),2,IF(UPPER(G9)=UPPER('Race Results'!G6),1,0))))))) -> 2 | I9: Caballo De Mar | J9: =IF(I9="","",IF(UPPER(I9)=UPPER('Race Results'!B7),10,IF(UPPER(I9)=UPPER('Race Results'!C7),6,IF(UPPER(I9)=UPPER('Race Results'!D7),4,IF(UPPER(I9)=UPPER('Race Results'!E7),3,IF(UPPER(I9)=UPPER('Race Results'!F7),2,IF(UPPER(I9)=UPPER('Race Results'!G7),1,0))))))) -> 0 | K9: Conclave | L9: =IF(K9="","",IF(UPPER(K9)=UPPER('Race Results'!B8),10,IF(UPPER(K9)=UPPER('Race Results'!C8),6,IF(UPPER(K9)=UPPER('Race Results'!D8),4,IF(UPPER(K9)=UPPER('Race Results'!E8),3,IF(UPPER(K9)=UPPER('Race Results'!F8),2,IF(UPPER(K9)=UPPER('Race Results'!G8),1,0))))))) -> 0 | M9: =IF(COUNTA(D9,F9,H9,J9,L9)=0,"",SUM(D9,F9,H9,J9,L9)) -> 4
A10: 7 | B10: Bryan White | C10: Pikachu | D10: =IF(C10="","",IF(UPPER(C10)=UPPER('Race Results'!B4),10,IF(UPPER(C10)=UPPER('Race Results'!C4),6,IF(UPPER(C10)=UPPER('Race Results'!D4),4,IF(UPPER(C10)=UPPER('Race Results'!E4),3,IF(UPPER(C10)=UPPER('Race Results'!F4),2,IF(UPPER(C10)=UPPER('Race Results'!G4),1,0))))))) -> 6 | E10: Guildmaster | F10: =IF(E10="","",IF(UPPER(E10)=UPPER('Race Results'!B5),10,IF(UPPER(E10)=UPPER('Race Results'!C5),6,IF(UPPER(E10)=UPPER('Race Results'!D5),4,IF(UPPER(E10)=UPPER('Race Results'!E5),3,IF(UPPER(E10)=UPPER('Race Results'!F5),2,IF(UPPER(E10)=UPPER('Race Results'!G5),1,0))))))) -> 10 | G10: Golden Orbit | H10: =IF(G10="","",IF(UPPER(G10)=UPPER('Race Results'!B6),10,IF(UPPER(G10)=UPPER('Race Results'!C6),6,IF(UPPER(G10)=UPPER('Race Results'!D6),4,IF(UPPER(G10)=UPPER('Race Results'!E6),3,IF(UPPER(G10)=UPPER('Race Results'!F6),2,IF(UPPER(G10)=UPPER('Race Results'!G6),1,0))))))) -> 1 | I10: Furthur | J10: =IF(I10="","",IF(UPPER(I10)=UPPER('Race Results'!B7),10,IF(UPPER(I10)=UPPER('Race Results'!C7),6,IF(UPPER(I10)=UPPER('Race Results'!D7),4,IF(UPPER(I10)=UPPER('Race Results'!E7),3,IF(UPPER(I10)=UPPER('Race Results'!F7),2,IF(UPPER(I10)=UPPER('Race Results'!G7),1,0))))))) -> 0 | K10: Moonfall | L10: =IF(K10="","",IF(UPPER(K10)=UPPER('Race Results'!B8),10,IF(UPPER(K10)=UPPER('Race Results'!C8),6,IF(UPPER(K10)=UPPER('Race Results'!D8),4,IF(UPPER(K10)=UPPER('Race Results'!E8),3,IF(UPPER(K10)=UPPER('Race Results'!F8),2,IF(UPPER(K10)=UPPER('Race Results'!G8),1,0))))))) -> 0 | M10: =IF(COUNTA(D10,F10,H10,J10,L10)=0,"",SUM(D10,F10,H10,J10,L10)) -> 17
A11: 8 | B11: Ryan Crowley | C11: Aix La Chapelle | D11: =IF(C11="","",IF(UPPER(C11)=UPPER('Race Results'!B4),10,IF(UPPER(C11)=UPPER('Race Results'!C4),6,IF(UPPER(C11)=UPPER('Race Results'!D4),4,IF(UPPER(C11)=UPPER('Race Results'!E4),3,IF(UPPER(C11)=UPPER('Race Results'!F4),2,IF(UPPER(C11)=UPPER('Race Results'!G4),1,0))))))) -> 0 | E11: Bnaider | F11: =IF(E11="","",IF(UPPER(E11)=UPPER('Race Results'!B5),10,IF(UPPER(E11)=UPPER('Race Results'!C5),6,IF(UPPER(E11)=UPPER('Race Results'!D5),4,IF(UPPER(E11)=UPPER('Race Results'!E5),3,IF(UPPER(E11)=UPPER('Race Results'!F5),2,IF(UPPER(E11)=UPPER('Race Results'!G5),1,0))))))) -> 0 | G11: Earth Shot | H11: =IF(G11="","",IF(UPPER(G11)=UPPER('Race Results'!B6),10,IF(UPPER(G11)=UPPER('Race Results'!C6),6,IF(UPPER(G11)=UPPER('Race Results'!D6),4,IF(UPPER(G11)=UPPER('Race Results'!E6),3,IF(UPPER(G11)=UPPER('Race Results'!F6),2,IF(UPPER(G11)=UPPER('Race Results'!G6),1,0))))))) -> 6 | I11: Sweet William | J11: =IF(I11="","",IF(UPPER(I11)=UPPER('Race Results'!B7),10,IF(UPPER(I11)=UPPER('Race Results'!C7),6,IF(UPPER(I11)=UPPER('Race Results'!D7),4,IF(UPPER(I11)=UPPER('Race Results'!E7),3,IF(UPPER(I11)=UPPER('Race Results'!F7),2,IF(UPPER(I11)=UPPER('Race Results'!G7),1,0))))))) -> 0 | K11: Langstone | L11: =IF(K11="","",IF(UPPER(K11)=UPPER('Race Results'!B8),10,IF(UPPER(K11)=UPPER('Race Results'!C8),6,IF(UPPER(K11)=UPPER('Race Results'!D8),4,IF(UPPER(K11)=UPPER('Race Results'!E8),3,IF(UPPER(K11)=UPPER('Race Results'!F8),2,IF(UPPER(K11)=UPPER('Race Results'!G8),1,0))))))) -> 0 | M11: =IF(COUNTA(D11,F11,H11,J11,L11)=0,"",SUM(D11,F11,H11,J11,L11)) -> 6
A12: 9 | B12: Vahi Crowley | C12: Romanza | D12: =IF(C12="","",IF(UPPER(C12)=UPPER('Race Results'!B4),10,IF(UPPER(C12)=UPPER('Race Results'!C4),6,IF(UPPER(C12)=UPPER('Race Results'!D4),4,IF(UPPER(C12)=UPPER('Race Results'!E4),3,IF(UPPER(C12)=UPPER('Race Results'!F4),2,IF(UPPER(C12)=UPPER('Race Results'!G4),1,0))))))) -> 10 | E12: Atomic City | F12: =IF(E12="","",IF(UPPER(E12)=UPPER('Race Results'!B5),10,IF(UPPER(E12)=UPPER('Race Results'!C5),6,IF(UPPER(E12)=UPPER('Race Results'!D5),4,IF(UPPER(E12)=UPPER('Race Results'!E5),3,IF(UPPER(E12)=UPPER('Race Results'!F5),2,IF(UPPER(E12)=UPPER('Race Results'!G5),1,0))))))) -> 6 | G12: Brilliant Star | H12: =IF(G12="","",IF(UPPER(G12)=UPPER('Race Results'!B6),10,IF(UPPER(G12)=UPPER('Race Results'!C6),6,IF(UPPER(G12)=UPPER('Race Results'!D6),4,IF(UPPER(G12)=UPPER('Race Results'!E6),3,IF(UPPER(G12)=UPPER('Race Results'!F6),2,IF(UPPER(G12)=UPPER('Race Results'!G6),1,0))))))) -> 4 | I12: Al Nayyir | J12: =IF(I12="","",IF(UPPER(I12)=UPPER('Race Results'!B7),10,IF(UPPER(I12)=UPPER('Race Results'!C7),6,IF(UPPER(I12)=UPPER('Race Results'!D7),4,IF(UPPER(I12)=UPPER('Race Results'!E7),3,IF(UPPER(I12)=UPPER('Race Results'!F7),2,IF(UPPER(I12)=UPPER('Race Results'!G7),1,0))))))) -> 0 | K12: Charly | L12: =IF(K12="","",IF(UPPER(K12)=UPPER('Race Results'!B8),10,IF(UPPER(K12)=UPPER('Race Results'!C8),6,IF(UPPER(K12)=UPPER('Race Results'!D8),4,IF(UPPER(K12)=UPPER('Race Results'!E8),3,IF(UPPER(K12)=UPPER('Race Results'!F8),2,IF(UPPER(K12)=UPPER('Race Results'!G8),1,0))))))) -> 0 | M12: =IF(COUNTA(D12,F12,H12,J12,L12)=0,"",SUM(D12,F12,H12,J12,L12)) -> 20
A13: 10 | B13: David Owens | C13: Sydney Carton | D13: =IF(C13="","",IF(UPPER(C13)=UPPER('Race Results'!B4),10,IF(UPPER(C13)=UPPER('Race Results'!C4),6,IF(UPPER(C13)=UPPER('Race Results'!D4),4,IF(UPPER(C13)=UPPER('Race Results'!E4),3,IF(UPPER(C13)=UPPER('Race Results'!F4),2,IF(UPPER(C13)=UPPER('Race Results'!G4),1,0))))))) -> 4 | E13: Cannes | F13: =IF(E13="","",IF(UPPER(E13)=UPPER('Race Results'!B5),10,IF(UPPER(E13)=UPPER('Race Results'!C5),6,IF(UPPER(E13)=UPPER('Race Results'!D5),4,IF(UPPER(E13)=UPPER('Race Results'!E5),3,IF(UPPER(E13)=UPPER('Race Results'!F5),2,IF(UPPER(E13)=UPPER('Race Results'!G5),1,0))))))) -> 0 | G13: Maldives | H13: =IF(G13="","",IF(UPPER(G13)=UPPER('Race Results'!B6),10,IF(UPPER(G13)=UPPER('Race Results'!C6),6,IF(UPPER(G13)=UPPER('Race Results'!D6),4,IF(UPPER(G13)=UPPER('Race Results'!E6),3,IF(UPPER(G13)=UPPER('Race Results'!F6),2,IF(UPPER(G13)=UPPER('Race Results'!G6),1,0))))))) -> 10 | I13: Trawlerman | J13: =IF(I13="","",IF(UPPER(I13)=UPPER('Race Results'!B7),10,IF(UPPER(I13)=UPPER('Race Results'!C7),6,IF(UPPER(I13)=UPPER('Race Results'!D7),4,IF(UPPER(I13)=UPPER('Race Results'!E7),3,IF(UPPER(I13)=UPPER('Race Results'!F7),2,IF(UPPER(I13)=UPPER('Race Results'!G7),1,0))))))) -> 0 | K13: Wild Thoughts | L13: =IF(K13="","",IF(UPPER(K13)=UPPER('Race Results'!B8),10,IF(UPPER(K13)=UPPER('Race Results'!C8),6,IF(UPPER(K13)=UPPER('Race Results'!D8),4,IF(UPPER(K13)=UPPER('Race Results'!E8),3,IF(UPPER(K13)=UPPER('Race Results'!F8),2,IF(UPPER(K13)=UPPER('Race Results'!G8),1,0))))))) -> 0 | M13: =IF(COUNTA(D13,F13,H13,J13,L13)=0,"",SUM(D13,F13,H13,J13,L13)) -> 14
A14: 11 | B14: Ivan Bogdanov | C14: Whispering Moon | D14: =IF(C14="","",IF(UPPER(C14)=UPPER('Race Results'!B4),10,IF(UPPER(C14)=UPPER('Race Results'!C4),6,IF(UPPER(C14)=UPPER('Race Results'!D4),4,IF(UPPER(C14)=UPPER('Race Results'!E4),3,IF(UPPER(C14)=UPPER('Race Results'!F4),2,IF(UPPER(C14)=UPPER('Race Results'!G4),1,0))))))) -> 0 | E14: Believed | F14: =IF(E14="","",IF(UPPER(E14)=UPPER('Race Results'!B5),10,IF(UPPER(E14)=UPPER('Race Results'!C5),6,IF(UPPER(E14)=UPPER('Race Results'!D5),4,IF(UPPER(E14)=UPPER('Race Results'!E5),3,IF(UPPER(E14)=UPPER('Race Results'!F5),2,IF(UPPER(E14)=UPPER('Race Results'!G5),1,0))))))) -> 0 | G14: Earth Shot | H14: =IF(G14="","",IF(UPPER(G14)=UPPER('Race Results'!B6),10,IF(UPPER(G14)=UPPER('Race Results'!C6),6,IF(UPPER(G14)=UPPER('Race Results'!D6),4,IF(UPPER(G14)=UPPER('Race Results'!E6),3,IF(UPPER(G14)=UPPER('Race Results'!F6),2,IF(UPPER(G14)=UPPER('Race Results'!G6),1,0))))))) -> 6 | I14: Sweet William | J14: =IF(I14="","",IF(UPPER(I14)=UPPER('Race Results'!B7),10,IF(UPPER(I14)=UPPER('Race Results'!C7),6,IF(UPPER(I14)=UPPER('Race Results'!D7),4,IF(UPPER(I14)=UPPER('Race Results'!E7),3,IF(UPPER(I14)=UPPER('Race Results'!F7),2,IF(UPPER(I14)=UPPER('Race Results'!G7),1,0))))))) -> 0 | K14: Moonfall | L14: =IF(K14="","",IF(UPPER(K14)=UPPER('Race Results'!B8),10,IF(UPPER(K14)=UPPER('Race Results'!C8),6,IF(UPPER(K14)=UPPER('Race Results'!D8),4,IF(UPPER(K14)=UPPER('Race Results'!E8),3,IF(UPPER(K14)=UPPER('Race Results'!F8),2,IF(UPPER(K14)=UPPER('Race Results'!G8),1,0))))))) -> 0 | M14: =IF(COUNTA(D14,F14,H14,J14,L14)=0,"",SUM(D14,F14,H14,J14,L14)) -> 6
A15: 12 | B15: Stephen Hughes | C15: Nola Soul | D15: =IF(C15="","",IF(UPPER(C15)=UPPER('Race Results'!B4),10,IF(UPPER(C15)=UPPER('Race Results'!C4),6,IF(UPPER(C15)=UPPER('Race Results'!D4),4,IF(UPPER(C15)=UPPER('Race Results'!E4),3,IF(UPPER(C15)=UPPER('Race Results'!F4),2,IF(UPPER(C15)=UPPER('Race Results'!G4),1,0))))))) -> 3 | E15: Guildmaster | F15: =IF(E15="","",IF(UPPER(E15)=UPPER('Race Results'!B5),10,IF(UPPER(E15)=UPPER('Race Results'!C5),6,IF(UPPER(E15)=UPPER('Race Results'!D5),4,IF(UPPER(E15)=UPPER('Race Results'!E5),3,IF(UPPER(E15)=UPPER('Race Results'!F5),2,IF(UPPER(E15)=UPPER('Race Results'!G5),1,0))))))) -> 10 | G15: Lady Roisia | H15: =IF(G15="","",IF(UPPER(G15)=UPPER('Race Results'!B6),10,IF(UPPER(G15)=UPPER('Race Results'!C6),6,IF(UPPER(G15)=UPPER('Race Results'!D6),4,IF(UPPER(G15)=UPPER('Race Results'!E6),3,IF(UPPER(G15)=UPPER('Race Results'!F6),2,IF(UPPER(G15)=UPPER('Race Results'!G6),1,0))))))) -> 3 | I15: Scandinavia | J15: =IF(I15="","",IF(UPPER(I15)=UPPER('Race Results'!B7),10,IF(UPPER(I15)=UPPER('Race Results'!C7),6,IF(UPPER(I15)=UPPER('Race Results'!D7),4,IF(UPPER(I15)=UPPER('Race Results'!E7),3,IF(UPPER(I15)=UPPER('Race Results'!F7),2,IF(UPPER(I15)=UPPER('Race Results'!G7),1,0))))))) -> 0 | K15: New Monarch | L15: =IF(K15="","",IF(UPPER(K15)=UPPER('Race Results'!B8),10,IF(UPPER(K15)=UPPER('Race Results'!C8),6,IF(UPPER(K15)=UPPER('Race Results'!D8),4,IF(UPPER(K15)=UPPER('Race Results'!E8),3,IF(UPPER(K15)=UPPER('Race Results'!F8),2,IF(UPPER(K15)=UPPER('Race Results'!G8),1,0))))))) -> 0 | M15: =IF(COUNTA(D15,F15,H15,J15,L15)=0,"",SUM(D15,F15,H15,J15,L15)) -> 16
A16: 13 | B16: David Hughes | C16: Pikachu | D16: =IF(C16="","",IF(UPPER(C16)=UPPER('Race Results'!B4),10,IF(UPPER(C16)=UPPER('Race Results'!C4),6,IF(UPPER(C16)=UPPER('Race Results'!D4),4,IF(UPPER(C16)=UPPER('Race Results'!E4),3,IF(UPPER(C16)=UPPER('Race Results'!F4),2,IF(UPPER(C16)=UPPER('Race Results'!G4),1,0))))))) -> 6 | E16: Atomic City | F16: =IF(E16="","",IF(UPPER(E16)=UPPER('Race Results'!B5),10,IF(UPPER(E16)=UPPER('Race Results'!C5),6,IF(UPPER(E16)=UPPER('Race Results'!D5),4,IF(UPPER(E16)=UPPER('Race Results'!E5),3,IF(UPPER(E16)=UPPER('Race Results'!F5),2,IF(UPPER(E16)=UPPER('Race Results'!G5),1,0))))))) -> 6 | G16: Venetia | H16: =IF(G16="","",IF(UPPER(G16)=UPPER('Race Results'!B6),10,IF(UPPER(G16)=UPPER('Race Results'!C6),6,IF(UPPER(G16)=UPPER('Race Results'!D6),4,IF(UPPER(G16)=UPPER('Race Results'!E6),3,IF(UPPER(G16)=UPPER('Race Results'!F6),2,IF(UPPER(G16)=UPPER('Race Results'!G6),1,0))))))) -> 2 | I16: Caballo De Mar | J16: =IF(I16="","",IF(UPPER(I16)=UPPER('Race Results'!B7),10,IF(UPPER(I16)=UPPER('Race Results'!C7),6,IF(UPPER(I16)=UPPER('Race Results'!D7),4,IF(UPPER(I16)=UPPER('Race Results'!E7),3,IF(UPPER(I16)=UPPER('Race Results'!F7),2,IF(UPPER(I16)=UPPER('Race Results'!G7),1,0))))))) -> 0 | K16: Langstone | L16: =IF(K16="","",IF(UPPER(K16)=UPPER('Race Results'!B8),10,IF(UPPER(K16)=UPPER('Race Results'!C8),6,IF(UPPER(K16)=UPPER('Race Results'!D8),4,IF(UPPER(K16)=UPPER('Race Results'!E8),3,IF(UPPER(K16)=UPPER('Race Results'!F8),2,IF(UPPER(K16)=UPPER('Race Results'!G8),1,0))))))) -> 0 | M16: =IF(COUNTA(D16,F16,H16,J16,L16)=0,"",SUM(D16,F16,H16,J16,L16)) -> 14
A17: 14 | B17: Gemma Forsyth | C17: Romanza | D17: =IF(C17="","",IF(UPPER(C17)=UPPER('Race Results'!B4),10,IF(UPPER(C17)=UPPER('Race Results'!C4),6,IF(UPPER(C17)=UPPER('Race Results'!D4),4,IF(UPPER(C17)=UPPER('Race Results'!E4),3,IF(UPPER(C17)=UPPER('Race Results'!F4),2,IF(UPPER(C17)=UPPER('Race Results'!G4),1,0))))))) -> 10 | E17: Heyzoom | F17: =IF(E17="","",IF(UPPER(E17)=UPPER('Race Results'!B5),10,IF(UPPER(E17)=UPPER('Race Results'!C5),6,IF(UPPER(E17)=UPPER('Race Results'!D5),4,IF(UPPER(E17)=UPPER('Race Results'!E5),3,IF(UPPER(E17)=UPPER('Race Results'!F5),2,IF(UPPER(E17)=UPPER('Race Results'!G5),1,0))))))) -> 0 | G17: Maldives | H17: =IF(G17="","",IF(UPPER(G17)=UPPER('Race Results'!B6),10,IF(UPPER(G17)=UPPER('Race Results'!C6),6,IF(UPPER(G17)=UPPER('Race Results'!D6),4,IF(UPPER(G17)=UPPER('Race Results'!E6),3,IF(UPPER(G17)=UPPER('Race Results'!F6),2,IF(UPPER(G17)=UPPER('Race Results'!G6),1,0))))))) -> 10 | I17: Furthur | J17: =IF(I17="","",IF(UPPER(I17)=UPPER('Race Results'!B7),10,IF(UPPER(I17)=UPPER('Race Results'!C7),6,IF(UPPER(I17)=UPPER('Race Results'!D7),4,IF(UPPER(I17)=UPPER('Race Results'!E7),3,IF(UPPER(I17)=UPPER('Race Results'!F7),2,IF(UPPER(I17)=UPPER('Race Results'!G7),1,0))))))) -> 0 | K17: Wise Prince | L17: =IF(K17="","",IF(UPPER(K17)=UPPER('Race Results'!B8),10,IF(UPPER(K17)=UPPER('Race Results'!C8),6,IF(UPPER(K17)=UPPER('Race Results'!D8),4,IF(UPPER(K17)=UPPER('Race Results'!E8),3,IF(UPPER(K17)=UPPER('Race Results'!F8),2,IF(UPPER(K17)=UPPER('Race Results'!G8),1,0))))))) -> 0 | M17: =IF(COUNTA(D17,F17,H17,J17,L17)=0,"",SUM(D17,F17,H17,J17,L17)) -> 20
A18: 15 | B18: Andy Bugler | C18: Revels | D18: =IF(C18="","",IF(UPPER(C18)=UPPER('Race Results'!B4),10,IF(UPPER(C18)=UPPER('Race Results'!C4),6,IF(UPPER(C18)=UPPER('Race Results'!D4),4,IF(UPPER(C18)=UPPER('Race Results'!E4),3,IF(UPPER(C18)=UPPER('Race Results'!F4),2,IF(UPPER(C18)=UPPER('Race Results'!G4),1,0))))))) -> 2 | E18: Bnaider | F18: =IF(E18="","",IF(UPPER(E18)=UPPER('Race Results'!B5),10,IF(UPPER(E18)=UPPER('Race Results'!C5),6,IF(UPPER(E18)=UPPER('Race Results'!D5),4,IF(UPPER(E18)=UPPER('Race Results'!E5),3,IF(UPPER(E18)=UPPER('Race Results'!F5),2,IF(UPPER(E18)=UPPER('Race Results'!G5),1,0))))))) -> 0 | G18: Brilliant Star | H18: =IF(G18="","",IF(UPPER(G18)=UPPER('Race Results'!B6),10,IF(UPPER(G18)=UPPER('Race Results'!C6),6,IF(UPPER(G18)=UPPER('Race Results'!D6),4,IF(UPPER(G18)=UPPER('Race Results'!E6),3,IF(UPPER(G18)=UPPER('Race Results'!F6),2,IF(UPPER(G18)=UPPER('Race Results'!G6),1,0))))))) -> 4 | I18: Sweet William | J18: =IF(I18="","",IF(UPPER(I18)=UPPER('Race Results'!B7),10,IF(UPPER(I18)=UPPER('Race Results'!C7),6,IF(UPPER(I18)=UPPER('Race Results'!D7),4,IF(UPPER(I18)=UPPER('Race Results'!E7),3,IF(UPPER(I18)=UPPER('Race Results'!F7),2,IF(UPPER(I18)=UPPER('Race Results'!G7),1,0))))))) -> 0 | K18: Charly | L18: =IF(K18="","",IF(UPPER(K18)=UPPER('Race Results'!B8),10,IF(UPPER(K18)=UPPER('Race Results'!C8),6,IF(UPPER(K18)=UPPER('Race Results'!D8),4,IF(UPPER(K18)=UPPER('Race Results'!E8),3,IF(UPPER(K18)=UPPER('Race Results'!F8),2,IF(UPPER(K18)=UPPER('Race Results'!G8),1,0))))))) -> 0 | M18: =IF(COUNTA(D18,F18,H18,J18,L18)=0,"",SUM(D18,F18,H18,J18,L18)) -> 6
A19: 16 | B19: Liz Bugler | C19: Bayside | D19: =IF(C19="","",IF(UPPER(C19)=UPPER('Race Results'!B4),10,IF(UPPER(C19)=UPPER('Race Results'!C4),6,IF(UPPER(C19)=UPPER('Race Results'!D4),4,IF(UPPER(C19)=UPPER('Race Results'!E4),3,IF(UPPER(C19)=UPPER('Race Results'!F4),2,IF(UPPER(C19)=UPPER('Race Results'!G4),1,0))))))) -> 1 | E19: Cannes | F19: =IF(E19="","",IF(UPPER(E19)=UPPER('Race Results'!B5),10,IF(UPPER(E19)=UPPER('Race Results'!C5),6,IF(UPPER(E19)=UPPER('Race Results'!D5),4,IF(UPPER(E19)=UPPER('Race Results'!E5),3,IF(UPPER(E19)=UPPER('Race Results'!F5),2,IF(UPPER(E19)=UPPER('Race Results'!G5),1,0))))))) -> 0 | G19: Golden Orbit | H19: =IF(G19="","",IF(UPPER(G19)=UPPER('Race Results'!B6),10,IF(UPPER(G19)=UPPER('Race Results'!C6),6,IF(UPPER(G19)=UPPER('Race Results'!D6),4,IF(UPPER(G19)=UPPER('Race Results'!E6),3,IF(UPPER(G19)=UPPER('Race Results'!F6),2,IF(UPPER(G19)=UPPER('Race Results'!G6),1,0))))))) -> 1 | I19: Al Riffa | J19: =IF(I19="","",IF(UPPER(I19)=UPPER('Race Results'!B7),10,IF(UPPER(I19)=UPPER('Race Results'!C7),6,IF(UPPER(I19)=UPPER('Race Results'!D7),4,IF(UPPER(I19)=UPPER('Race Results'!E7),3,IF(UPPER(I19)=UPPER('Race Results'!F7),2,IF(UPPER(I19)=UPPER('Race Results'!G7),1,0))))))) -> 0 | K19: Conclave | L19: =IF(K19="","",IF(UPPER(K19)=UPPER('Race Results'!B8),10,IF(UPPER(K19)=UPPER('Race Results'!C8),6,IF(UPPER(K19)=UPPER('Race Results'!D8),4,IF(UPPER(K19)=UPPER('Race Results'!E8),3,IF(UPPER(K19)=UPPER('Race Results'!F8),2,IF(UPPER(K19)=UPPER('Race Results'!G8),1,0))))))) -> 0 | M19: =IF(COUNTA(D19,F19,H19,J19,L19)=0,"",SUM(D19,F19,H19,J19,L19)) -> 2
A20: 17 | B20: Emily Sardo | C20: Romanza | D20: =IF(C20="","",IF(UPPER(C20)=UPPER('Race Results'!B4),10,IF(UPPER(C20)=UPPER('Race Results'!C4),6,IF(UPPER(C20)=UPPER('Race Results'!D4),4,IF(UPPER(C20)=UPPER('Race Results'!E4),3,IF(UPPER(C20)=UPPER('Race Results'!F4),2,IF(UPPER(C20)=UPPER('Race Results'!G4),1,0))))))) -> 10 | E20: Guildmaster | F20: =IF(E20="","",IF(UPPER(E20)=UPPER('Race Results'!B5),10,IF(UPPER(E20)=UPPER('Race Results'!C5),6,IF(UPPER(E20)=UPPER('Race Results'!D5),4,IF(UPPER(E20)=UPPER('Race Results'!E5),3,IF(UPPER(E20)=UPPER('Race Results'!F5),2,IF(UPPER(E20)=UPPER('Race Results'!G5),1,0))))))) -> 10 | G20: Maldives | H20: =IF(G20="","",IF(UPPER(G20)=UPPER('Race Results'!B6),10,IF(UPPER(G20)=UPPER('Race Results'!C6),6,IF(UPPER(G20)=UPPER('Race Results'!D6),4,IF(UPPER(G20)=UPPER('Race Results'!E6),3,IF(UPPER(G20)=UPPER('Race Results'!F6),2,IF(UPPER(G20)=UPPER('Race Results'!G6),1,0))))))) -> 10 | I20: Sweet William | J20: =IF(I20="","",IF(UPPER(I20)=UPPER('Race Results'!B7),10,IF(UPPER(I20)=UPPER('Race Results'!C7),6,IF(UPPER(I20)=UPPER('Race Results'!D7),4,IF(UPPER(I20)=UPPER('Race Results'!E7),3,IF(UPPER(I20)=UPPER('Race Results'!F7),2,IF(UPPER(I20)=UPPER('Race Results'!G7),1,0))))))) -> 0 | K20: Moonfall | L20: =IF(K20="","",IF(UPPER(K20)=UPPER('Race Results'!B8),10,IF(UPPER(K20)=UPPER('Race Results'!C8),6,IF(UPPER(K20)=UPPER('Race Results'!D8),4,IF(UPPER(K20)=UPPER('Race Results'!E8),3,IF(UPPER(K20)=UPPER('Race Results'!F8),2,IF(UPPER(K20)=UPPER('Race Results'!G8),1,0))))))) -> 0 | M20: =IF(COUNTA(D20,F20,H20,J20,L20)=0,"",SUM(D20,F20,H20,J20,L20)) -> 30
A21: 18 | B21: Darren Gill | C21: On Just Terms | D21: =IF(C21="","",IF(UPPER(C21)=UPPER('Race Results'!B4),10,IF(UPPER(C21)=UPPER('Race Results'!C4),6,IF(UPPER(C21)=UPPER('Race Results'!D4),4,IF(UPPER(C21)=UPPER('Race Results'!E4),3,IF(UPPER(C21)=UPPER('Race Results'!F4),2,IF(UPPER(C21)=UPPER('Race Results'!G4),1,0))))))) -> 0 | E21: Atomic City | F21: =IF(E21="","",IF(UPPER(E21)=UPPER('Race Results'!B5),10,IF(UPPER(E21)=UPPER('Race Results'!C5),6,IF(UPPER(E21)=UPPER('Race Results'!D5),4,IF(UPPER(E21)=UPPER('Race Results'!E5),3,IF(UPPER(E21)=UPPER('Race Results'!F5),2,IF(UPPER(E21)=UPPER('Race Results'!G5),1,0))))))) -> 6 | G21: Earth Shot | H21: =IF(G21="","",IF(UPPER(G21)=UPPER('Race Results'!B6),10,IF(UPPER(G21)=UPPER('Race Results'!C6),6,IF(UPPER(G21)=UPPER('Race Results'!D6),4,IF(UPPER(G21)=UPPER('Race Results'!E6),3,IF(UPPER(G21)=UPPER('Race Results'!F6),2,IF(UPPER(G21)=UPPER('Race Results'!G6),1,0))))))) -> 6 | I21: Trawlerman | J21: =IF(I21="","",IF(UPPER(I21)=UPPER('Race Results'!B7),10,IF(UPPER(I21)=UPPER('Race Results'!C7),6,IF(UPPER(I21)=UPPER('Race Results'!D7),4,IF(UPPER(I21)=UPPER('Race Results'!E7),3,IF(UPPER(I21)=UPPER('Race Results'!F7),2,IF(UPPER(I21)=UPPER('Race Results'!G7),1,0))))))) -> 0 | K21: Pathein | L21: =IF(K21="","",IF(UPPER(K21)=UPPER('Race Results'!B8),10,IF(UPPER(K21)=UPPER('Race Results'!C8),6,IF(UPPER(K21)=UPPER('Race Results'!D8),4,IF(UPPER(K21)=UPPER('Race Results'!E8),3,IF(UPPER(K21)=UPPER('Race Results'!F8),2,IF(UPPER(K21)=UPPER('Race Results'!G8),1,0))))))) -> 0 | M21: =IF(COUNTA(D21,F21,H21,J21,L21)=0,"",SUM(D21,F21,H21,J21,L21)) -> 12
A22: 19 | B22: Lynn Forsyth | C22: Sydney Carton | D22: =IF(C22="","",IF(UPPER(C22)=UPPER('Race Results'!B4),10,IF(UPPER(C22)=UPPER('Race Results'!C4),6,IF(UPPER(C22)=UPPER('Race Results'!D4),4,IF(UPPER(C22)=UPPER('Race Results'!E4),3,IF(UPPER(C22)=UPPER('Race Results'!F4),2,IF(UPPER(C22)=UPPER('Race Results'!G4),1,0))))))) -> 4 | E22: Believed | F22: =IF(E22="","",IF(UPPER(E22)=UPPER('Race Results'!B5),10,IF(UPPER(E22)=UPPER('Race Results'!C5),6,IF(UPPER(E22)=UPPER('Race Results'!D5),4,IF(UPPER(E22)=UPPER('Race Results'!E5),3,IF(UPPER(E22)=UPPER('Race Results'!F5),2,IF(UPPER(E22)=UPPER('Race Results'!G5),1,0))))))) -> 0 | G22: Lady Roisia | H22: =IF(G22="","",IF(UPPER(G22)=UPPER('Race Results'!B6),10,IF(UPPER(G22)=UPPER('Race Results'!C6),6,IF(UPPER(G22)=UPPER('Race Results'!D6),4,IF(UPPER(G22)=UPPER('Race Results'!E6),3,IF(UPPER(G22)=UPPER('Race Results'!F6),2,IF(UPPER(G22)=UPPER('Race Results'!G6),1,0))))))) -> 3 | I22: Scandinavia | J22: =IF(I22="","",IF(UPPER(I22)=UPPER('Race Results'!B7),10,IF(UPPER(I22)=UPPER('Race Results'!C7),6,IF(UPPER(I22)=UPPER('Race Results'!D7),4,IF(UPPER(I22)=UPPER('Race Results'!E7),3,IF(UPPER(I22)=UPPER('Race Results'!F7),2,IF(UPPER(I22)=UPPER('Race Results'!G7),1,0))))))) -> 0 | K22: Langstone | L22: =IF(K22="","",IF(UPPER(K22)=UPPER('Race Results'!B8),10,IF(UPPER(K22)=UPPER('Race Results'!C8),6,IF(UPPER(K22)=UPPER('Race Results'!D8),4,IF(UPPER(K22)=UPPER('Race Results'!E8),3,IF(UPPER(K22)=UPPER('Race Results'!F8),2,IF(UPPER(K22)=UPPER('Race Results'!G8),1,0))))))) -> 0 | M22: =IF(COUNTA(D22,F22,H22,J22,L22)=0,"",SUM(D22,F22,H22,J22,L22)) -> 7
A23: 20 | B23: Peter Goode | C23: Pikachu | D23: =IF(C23="","",IF(UPPER(C23)=UPPER('Race Results'!B4),10,IF(UPPER(C23)=UPPER('Race Results'!C4),6,IF(UPPER(C23)=UPPER('Race Results'!D4),4,IF(UPPER(C23)=UPPER('Race Results'!E4),3,IF(UPPER(C23)=UPPER('Race Results'!F4),2,IF(UPPER(C23)=UPPER('Race Results'!G4),1,0))))))) -> 6 | E23: Heyzoom | F23: =IF(E23="","",IF(UPPER(E23)=UPPER('Race Results'!B5),10,IF(UPPER(E23)=UPPER('Race Results'!C5),6,IF(UPPER(E23)=UPPER('Race Results'!D5),4,IF(UPPER(E23)=UPPER('Race Results'!E5),3,IF(UPPER(E23)=UPPER('Race Results'!F5),2,IF(UPPER(E23)=UPPER('Race Results'!G5),1,0))))))) -> 0 | G23: Venetia | H23: =IF(G23="","",IF(UPPER(G23)=UPPER('Race Results'!B6),10,IF(UPPER(G23)=UPPER('Race Results'!C6),6,IF(UPPER(G23)=UPPER('Race Results'!D6),4,IF(UPPER(G23)=UPPER('Race Results'!E6),3,IF(UPPER(G23)=UPPER('Race Results'!F6),2,IF(UPPER(G23)=UPPER('Race Results'!G6),1,0))))))) -> 2 | I23: Caballo De Mar | J23: =IF(I23="","",IF(UPPER(I23)=UPPER('Race Results'!B7),10,IF(UPPER(I23)=UPPER('Race Results'!C7),6,IF(UPPER(I23)=UPPER('Race Results'!D7),4,IF(UPPER(I23)=UPPER('Race Results'!E7),3,IF(UPPER(I23)=UPPER('Race Results'!F7),2,IF(UPPER(I23)=UPPER('Race Results'!G7),1,0))))))) -> 0 | K23: New Monarch | L23: =IF(K23="","",IF(UPPER(K23)=UPPER('Race Results'!B8),10,IF(UPPER(K23)=UPPER('Race Results'!C8),6,IF(UPPER(K23)=UPPER('Race Results'!D8),4,IF(UPPER(K23)=UPPER('Race Results'!E8),3,IF(UPPER(K23)=UPPER('Race Results'!F8),2,IF(UPPER(K23)=UPPER('Race Results'!G8),1,0))))))) -> 0 | M23: =IF(COUNTA(D23,F23,H23,J23,L23)=0,"",SUM(D23,F23,H23,J23,L23)) -> 8
A24: 21 | B24: Steve Burfitt | C24: Romanza | D24: =IF(C24="","",IF(UPPER(C24)=UPPER('Race Results'!B4),10,IF(UPPER(C24)=UPPER('Race Results'!C4),6,IF(UPPER(C24)=UPPER('Race Results'!D4),4,IF(UPPER(C24)=UPPER('Race Results'!E4),3,IF(UPPER(C24)=UPPER('Race Results'!F4),2,IF(UPPER(C24)=UPPER('Race Results'!G4),1,0))))))) -> 10 | E24: Cannes | F24: =IF(E24="","",IF(UPPER(E24)=UPPER('Race Results'!B5),10,IF(UPPER(E24)=UPPER('Race Results'!C5),6,IF(UPPER(E24)=UPPER('Race Results'!D5),4,IF(UPPER(E24)=UPPER('Race Results'!E5),3,IF(UPPER(E24)=UPPER('Race Results'!F5),2,IF(UPPER(E24)=UPPER('Race Results'!G5),1,0))))))) -> 0 | G24: Maldives | H24: =IF(G24="","",IF(UPPER(G24)=UPPER('Race Results'!B6),10,IF(UPPER(G24)=UPPER('Race Results'!C6),6,IF(UPPER(G24)=UPPER('Race Results'!D6),4,IF(UPPER(G24)=UPPER('Race Results'!E6),3,IF(UPPER(G24)=UPPER('Race Results'!F6),2,IF(UPPER(G24)=UPPER('Race Results'!G6),1,0))))))) -> 10 | I24: Al Riffa | J24: =IF(I24="","",IF(UPPER(I24)=UPPER('Race Results'!B7),10,IF(UPPER(I24)=UPPER('Race Results'!C7),6,IF(UPPER(I24)=UPPER('Race Results'!D7),4,IF(UPPER(I24)=UPPER('Race Results'!E7),3,IF(UPPER(I24)=UPPER('Race Results'!F7),2,IF(UPPER(I24)=UPPER('Race Results'!G7),1,0))))))) -> 0 | K24: Charly | L24: =IF(K24="","",IF(UPPER(K24)=UPPER('Race Results'!B8),10,IF(UPPER(K24)=UPPER('Race Results'!C8),6,IF(UPPER(K24)=UPPER('Race Results'!D8),4,IF(UPPER(K24)=UPPER('Race Results'!E8),3,IF(UPPER(K24)=UPPER('Race Results'!F8),2,IF(UPPER(K24)=UPPER('Race Results'!G8),1,0))))))) -> 0 | M24: =IF(COUNTA(D24,F24,H24,J24,L24)=0,"",SUM(D24,F24,H24,J24,L24)) -> 20
A25: 22 | B25: Mick Hogg | C25: Nola Soul | D25: =IF(C25="","",IF(UPPER(C25)=UPPER('Race Results'!B4),10,IF(UPPER(C25)=UPPER('Race Results'!C4),6,IF(UPPER(C25)=UPPER('Race Results'!D4),4,IF(UPPER(C25)=UPPER('Race Results'!E4),3,IF(UPPER(C25)=UPPER('Race Results'!F4),2,IF(UPPER(C25)=UPPER('Race Results'!G4),1,0))))))) -> 3 | E25: Guildmaster | F25: =IF(E25="","",IF(UPPER(E25)=UPPER('Race Results'!B5),10,IF(UPPER(E25)=UPPER('Race Results'!C5),6,IF(UPPER(E25)=UPPER('Race Results'!D5),4,IF(UPPER(E25)=UPPER('Race Results'!E5),3,IF(UPPER(E25)=UPPER('Race Results'!F5),2,IF(UPPER(E25)=UPPER('Race Results'!G5),1,0))))))) -> 10 | G25: Brilliant Star | H25: =IF(G25="","",IF(UPPER(G25)=UPPER('Race Results'!B6),10,IF(UPPER(G25)=UPPER('Race Results'!C6),6,IF(UPPER(G25)=UPPER('Race Results'!D6),4,IF(UPPER(G25)=UPPER('Race Results'!E6),3,IF(UPPER(G25)=UPPER('Race Results'!F6),2,IF(UPPER(G25)=UPPER('Race Results'!G6),1,0))))))) -> 4 | I25: Sweet William | J25: =IF(I25="","",IF(UPPER(I25)=UPPER('Race Results'!B7),10,IF(UPPER(I25)=UPPER('Race Results'!C7),6,IF(UPPER(I25)=UPPER('Race Results'!D7),4,IF(UPPER(I25)=UPPER('Race Results'!E7),3,IF(UPPER(I25)=UPPER('Race Results'!F7),2,IF(UPPER(I25)=UPPER('Race Results'!G7),1,0))))))) -> 0 | K25: Moonfall | L25: =IF(K25="","",IF(UPPER(K25)=UPPER('Race Results'!B8),10,IF(UPPER(K25)=UPPER('Race Results'!C8),6,IF(UPPER(K25)=UPPER('Race Results'!D8),4,IF(UPPER(K25)=UPPER('Race Results'!E8),3,IF(UPPER(K25)=UPPER('Race Results'!F8),2,IF(UPPER(K25)=UPPER('Race Results'!G8),1,0))))))) -> 0 | M25: =IF(COUNTA(D25,F25,H25,J25,L25)=0,"",SUM(D25,F25,H25,J25,L25)) -> 17
A26: 23 | B26: Liam Bridgeman | C26: Revels | D26: =IF(C26="","",IF(UPPER(C26)=UPPER('Race Results'!B4),10,IF(UPPER(C26)=UPPER('Race Results'!C4),6,IF(UPPER(C26)=UPPER('Race Results'!D4),4,IF(UPPER(C26)=UPPER('Race Results'!E4),3,IF(UPPER(C26)=UPPER('Race Results'!F4),2,IF(UPPER(C26)=UPPER('Race Results'!G4),1,0))))))) -> 2 | E26: Atomic City | F26: =IF(E26="","",IF(UPPER(E26)=UPPER('Race Results'!B5),10,IF(UPPER(E26)=UPPER('Race Results'!C5),6,IF(UPPER(E26)=UPPER('Race Results'!D5),4,IF(UPPER(E26)=UPPER('Race Results'!E5),3,IF(UPPER(E26)=UPPER('Race Results'!F5),2,IF(UPPER(E26)=UPPER('Race Results'!G5),1,0))))))) -> 6 | G26: Earth Shot | H26: =IF(G26="","",IF(UPPER(G26)=UPPER('Race Results'!B6),10,IF(UPPER(G26)=UPPER('Race Results'!C6),6,IF(UPPER(G26)=UPPER('Race Results'!D6),4,IF(UPPER(G26)=UPPER('Race Results'!E6),3,IF(UPPER(G26)=UPPER('Race Results'!F6),2,IF(UPPER(G26)=UPPER('Race Results'!G6),1,0))))))) -> 6 | I26: Furthur | J26: =IF(I26="","",IF(UPPER(I26)=UPPER('Race Results'!B7),10,IF(UPPER(I26)=UPPER('Race Results'!C7),6,IF(UPPER(I26)=UPPER('Race Results'!D7),4,IF(UPPER(I26)=UPPER('Race Results'!E7),3,IF(UPPER(I26)=UPPER('Race Results'!F7),2,IF(UPPER(I26)=UPPER('Race Results'!G7),1,0))))))) -> 0 | K26: Langstone | L26: =IF(K26="","",IF(UPPER(K26)=UPPER('Race Results'!B8),10,IF(UPPER(K26)=UPPER('Race Results'!C8),6,IF(UPPER(K26)=UPPER('Race Results'!D8),4,IF(UPPER(K26)=UPPER('Race Results'!E8),3,IF(UPPER(K26)=UPPER('Race Results'!F8),2,IF(UPPER(K26)=UPPER('Race Results'!G8),1,0))))))) -> 0 | M26: =IF(COUNTA(D26,F26,H26,J26,L26)=0,"",SUM(D26,F26,H26,J26,L26)) -> 14
A27: 24 | B27: Steve Hunt | C27: Whispering Moon | D27: =IF(C27="","",IF(UPPER(C27)=UPPER('Race Results'!B4),10,IF(UPPER(C27)=UPPER('Race Results'!C4),6,IF(UPPER(C27)=UPPER('Race Results'!D4),4,IF(UPPER(C27)=UPPER('Race Results'!E4),3,IF(UPPER(C27)=UPPER('Race Results'!F4),2,IF(UPPER(C27)=UPPER('Race Results'!G4),1,0))))))) -> 0 | E27: Bnaider | F27: =IF(E27="","",IF(UPPER(E27)=UPPER('Race Results'!B5),10,IF(UPPER(E27)=UPPER('Race Results'!C5),6,IF(UPPER(E27)=UPPER('Race Results'!D5),4,IF(UPPER(E27)=UPPER('Race Results'!E5),3,IF(UPPER(E27)=UPPER('Race Results'!F5),2,IF(UPPER(E27)=UPPER('Race Results'!G5),1,0))))))) -> 0 | G27: Lady Roisia | H27: =IF(G27="","",IF(UPPER(G27)=UPPER('Race Results'!B6),10,IF(UPPER(G27)=UPPER('Race Results'!C6),6,IF(UPPER(G27)=UPPER('Race Results'!D6),4,IF(UPPER(G27)=UPPER('Race Results'!E6),3,IF(UPPER(G27)=UPPER('Race Results'!F6),2,IF(UPPER(G27)=UPPER('Race Results'!G6),1,0))))))) -> 3 | I27: Trawlerman | J27: =IF(I27="","",IF(UPPER(I27)=UPPER('Race Results'!B7),10,IF(UPPER(I27)=UPPER('Race Results'!C7),6,IF(UPPER(I27)=UPPER('Race Results'!D7),4,IF(UPPER(I27)=UPPER('Race Results'!E7),3,IF(UPPER(I27)=UPPER('Race Results'!F7),2,IF(UPPER(I27)=UPPER('Race Results'!G7),1,0))))))) -> 0 | K27: Wise Prince | L27: =IF(K27="","",IF(UPPER(K27)=UPPER('Race Results'!B8),10,IF(UPPER(K27)=UPPER('Race Results'!C8),6,IF(UPPER(K27)=UPPER('Race Results'!D8),4,IF(UPPER(K27)=UPPER('Race Results'!E8),3,IF(UPPER(K27)=UPPER('Race Results'!F8),2,IF(UPPER(K27)=UPPER('Race Results'!G8),1,0))))))) -> 0 | M27: =IF(COUNTA(D27,F27,H27,J27,L27)=0,"",SUM(D27,F27,H27,J27,L27)) -> 3
A28: 25 | B28: Jack Webb | C28: Sea Venture | D28: =IF(C28="","",IF(UPPER(C28)=UPPER('Race Results'!B4),10,IF(UPPER(C28)=UPPER('Race Results'!C4),6,IF(UPPER(C28)=UPPER('Race Results'!D4),4,IF(UPPER(C28)=UPPER('Race Results'!E4),3,IF(UPPER(C28)=UPPER('Race Results'!F4),2,IF(UPPER(C28)=UPPER('Race Results'!G4),1,0))))))) -> 0 | E28: Cannes | F28: =IF(E28="","",IF(UPPER(E28)=UPPER('Race Results'!B5),10,IF(UPPER(E28)=UPPER('Race Results'!C5),6,IF(UPPER(E28)=UPPER('Race Results'!D5),4,IF(UPPER(E28)=UPPER('Race Results'!E5),3,IF(UPPER(E28)=UPPER('Race Results'!F5),2,IF(UPPER(E28)=UPPER('Race Results'!G5),1,0))))))) -> 0 | G28: Maldives | H28: =IF(G28="","",IF(UPPER(G28)=UPPER('Race Results'!B6),10,IF(UPPER(G28)=UPPER('Race Results'!C6),6,IF(UPPER(G28)=UPPER('Race Results'!D6),4,IF(UPPER(G28)=UPPER('Race Results'!E6),3,IF(UPPER(G28)=UPPER('Race Results'!F6),2,IF(UPPER(G28)=UPPER('Race Results'!G6),1,0))))))) -> 10 | I28: Sweet William | J28: =IF(I28="","",IF(UPPER(I28)=UPPER('Race Results'!B7),10,IF(UPPER(I28)=UPPER('Race Results'!C7),6,IF(UPPER(I28)=UPPER('Race Results'!D7),4,IF(UPPER(I28)=UPPER('Race Results'!E7),3,IF(UPPER(I28)=UPPER('Race Results'!F7),2,IF(UPPER(I28)=UPPER('Race Results'!G7),1,0))))))) -> 0 | K28: Conclave | L28: =IF(K28="","",IF(UPPER(K28)=UPPER('Race Results'!B8),10,IF(UPPER(K28)=UPPER('Race Results'!C8),6,IF(UPPER(K28)=UPPER('Race Results'!D8),4,IF(UPPER(K28)=UPPER('Race Results'!E8),3,IF(UPPER(K28)=UPPER('Race Results'!F8),2,IF(UPPER(K28)=UPPER('Race Results'!G8),1,0))))))) -> 0 | M28: =IF(COUNTA(D28,F28,H28,J28,L28)=0,"",SUM(D28,F28,H28,J28,L28)) -> 10
A29: 26 | B29: Jamie Jordan | C29: Romanza | D29: =IF(C29="","",IF(UPPER(C29)=UPPER('Race Results'!B4),10,IF(UPPER(C29)=UPPER('Race Results'!C4),6,IF(UPPER(C29)=UPPER('Race Results'!D4),4,IF(UPPER(C29)=UPPER('Race Results'!E4),3,IF(UPPER(C29)=UPPER('Race Results'!F4),2,IF(UPPER(C29)=UPPER('Race Results'!G4),1,0))))))) -> 10 | E29: Guildmaster | F29: =IF(E29="","",IF(UPPER(E29)=UPPER('Race Results'!B5),10,IF(UPPER(E29)=UPPER('Race Results'!C5),6,IF(UPPER(E29)=UPPER('Race Results'!D5),4,IF(UPPER(E29)=UPPER('Race Results'!E5),3,IF(UPPER(E29)=UPPER('Race Results'!F5),2,IF(UPPER(E29)=UPPER('Race Results'!G5),1,0))))))) -> 10 | G29: Venetia | H29: =IF(G29="","",IF(UPPER(G29)=UPPER('Race Results'!B6),10,IF(UPPER(G29)=UPPER('Race Results'!C6),6,IF(UPPER(G29)=UPPER('Race Results'!D6),4,IF(UPPER(G29)=UPPER('Race Results'!E6),3,IF(UPPER(G29)=UPPER('Race Results'!F6),2,IF(UPPER(G29)=UPPER('Race Results'!G6),1,0))))))) -> 2 | I29: Al Nayyir | J29: =IF(I29="","",IF(UPPER(I29)=UPPER('Race Results'!B7),10,IF(UPPER(I29)=UPPER('Race Results'!C7),6,IF(UPPER(I29)=UPPER('Race Results'!D7),4,IF(UPPER(I29)=UPPER('Race Results'!E7),3,IF(UPPER(I29)=UPPER('Race Results'!F7),2,IF(UPPER(I29)=UPPER('Race Results'!G7),1,0))))))) -> 0 | K29: Moonfall | L29: =IF(K29="","",IF(UPPER(K29)=UPPER('Race Results'!B8),10,IF(UPPER(K29)=UPPER('Race Results'!C8),6,IF(UPPER(K29)=UPPER('Race Results'!D8),4,IF(UPPER(K29)=UPPER('Race Results'!E8),3,IF(UPPER(K29)=UPPER('Race Results'!F8),2,IF(UPPER(K29)=UPPER('Race Results'!G8),1,0))))))) -> 0 | M29: =IF(COUNTA(D29,F29,H29,J29,L29)=0,"",SUM(D29,F29,H29,J29,L29)) -> 22
A30: 27 | B30: Jade Dally | C30: Pikachu | D30: =IF(C30="","",IF(UPPER(C30)=UPPER('Race Results'!B4),10,IF(UPPER(C30)=UPPER('Race Results'!C4),6,IF(UPPER(C30)=UPPER('Race Results'!D4),4,IF(UPPER(C30)=UPPER('Race Results'!E4),3,IF(UPPER(C30)=UPPER('Race Results'!F4),2,IF(UPPER(C30)=UPPER('Race Results'!G4),1,0))))))) -> 6 | E30: Believed | F30: =IF(E30="","",IF(UPPER(E30)=UPPER('Race Results'!B5),10,IF(UPPER(E30)=UPPER('Race Results'!C5),6,IF(UPPER(E30)=UPPER('Race Results'!D5),4,IF(UPPER(E30)=UPPER('Race Results'!E5),3,IF(UPPER(E30)=UPPER('Race Results'!F5),2,IF(UPPER(E30)=UPPER('Race Results'!G5),1,0))))))) -> 0 | G30: Golden Orbit | H30: =IF(G30="","",IF(UPPER(G30)=UPPER('Race Results'!B6),10,IF(UPPER(G30)=UPPER('Race Results'!C6),6,IF(UPPER(G30)=UPPER('Race Results'!D6),4,IF(UPPER(G30)=UPPER('Race Results'!E6),3,IF(UPPER(G30)=UPPER('Race Results'!F6),2,IF(UPPER(G30)=UPPER('Race Results'!G6),1,0))))))) -> 1 | I30: Scandinavia | J30: =IF(I30="","",IF(UPPER(I30)=UPPER('Race Results'!B7),10,IF(UPPER(I30)=UPPER('Race Results'!C7),6,IF(UPPER(I30)=UPPER('Race Results'!D7),4,IF(UPPER(I30)=UPPER('Race Results'!E7),3,IF(UPPER(I30)=UPPER('Race Results'!F7),2,IF(UPPER(I30)=UPPER('Race Results'!G7),1,0))))))) -> 0 | K30: Charly | L30: =IF(K30="","",IF(UPPER(K30)=UPPER('Race Results'!B8),10,IF(UPPER(K30)=UPPER('Race Results'!C8),6,IF(UPPER(K30)=UPPER('Race Results'!D8),4,IF(UPPER(K30)=UPPER('Race Results'!E8),3,IF(UPPER(K30)=UPPER('Race Results'!F8),2,IF(UPPER(K30)=UPPER('Race Results'!G8),1,0))))))) -> 0 | M30: =IF(COUNTA(D30,F30,H30,J30,L30)=0,"",SUM(D30,F30,H30,J30,L30)) -> 7
A31: 28 | D31: =IF(C31="","",IF(UPPER(C31)=UPPER('Race Results'!B4),10,IF(UPPER(C31)=UPPER('Race Results'!C4),6,IF(UPPER(C31)=UPPER('Race Results'!D4),4,IF(UPPER(C31)=UPPER('Race Results'!E4),3,IF(UPPER(C31)=UPPER('Race Results'!F4),2,IF(UPPER(C31)=UPPER('Race Results'!G4),1,0))))))) | F31: =IF(E31="","",IF(UPPER(E31)=UPPER('Race Results'!B5),10,IF(UPPER(E31)=UPPER('Race Results'!C5),6,IF(UPPER(E31)=UPPER('Race Results'!D5),4,IF(UPPER(E31)=UPPER('Race Results'!E5),3,IF(UPPER(E31)=UPPER('Race Results'!F5),2,IF(UPPER(E31)=UPPER('Race Results'!G5),1,0))))))) | H31: =IF(G31="","",IF(UPPER(G31)=UPPER('Race Results'!B6),10,IF(UPPER(G31)=UPPER('Race Results'!C6),6,IF(UPPER(G31)=UPPER('Race Results'!D6),4,IF(UPPER(G31)=UPPER('Race Results'!E6),3,IF(UPPER(G31)=UPPER('Race Results'!F6),2,IF(UPPER(G31)=UPPER('Race Results'!G6),1,0))))))) | J31: =IF(I31="","",IF(UPPER(I31)=UPPER('Race Results'!B7),10,IF(UPPER(I31)=UPPER('Race Results'!C7),6,IF(UPPER(I31)=UPPER('Race Results'!D7),4,IF(UPPER(I31)=UPPER('Race Results'!E7),3,IF(UPPER(I31)=UPPER('Race Results'!F7),2,IF(UPPER(I31)=UPPER('Race Results'!G7),1,0))))))) | L31: =IF(K31="","",IF(UPPER(K31)=UPPER('Race Results'!B8),10,IF(UPPER(K31)=UPPER('Race Results'!C8),6,IF(UPPER(K31)=UPPER('Race Results'!D8),4,IF(UPPER(K31)=UPPER('Race Results'!E8),3,IF(UPPER(K31)=UPPER('Race Results'!F8),2,IF(UPPER(K31)=UPPER('Race Results'!G8),1,0))))))) | M31: =IF(COUNTA(D31,F31,H31,J31,L31)=0,"",SUM(D31,F31,H31,J31,L31)) -> 0
A32: 29 | D32: =IF(C32="","",IF(UPPER(C32)=UPPER('Race Results'!B4),10,IF(UPPER(C32)=UPPER('Race Results'!C4),6,IF(UPPER(C32)=UPPER('Race Results'!D4),4,IF(UPPER(C32)=UPPER('Race Results'!E4),3,IF(UPPER(C32)=UPPER('Race Results'!F4),2,IF(UPPER(C32)=UPPER('Race Results'!G4),1,0))))))) | F32: =IF(E32="","",IF(UPPER(E32)=UPPER('Race Results'!B5),10,IF(UPPER(E32)=UPPER('Race Results'!C5),6,IF(UPPER(E32)=UPPER('Race Results'!D5),4,IF(UPPER(E32)=UPPER('Race Results'!E5),3,IF(UPPER(E32)=UPPER('Race Results'!F5),2,IF(UPPER(E32)=UPPER('Race Results'!G5),1,0))))))) | H32: =IF(G32="","",IF(UPPER(G32)=UPPER('Race Results'!B6),10,IF(UPPER(G32)=UPPER('Race Results'!C6),6,IF(UPPER(G32)=UPPER('Race Results'!D6),4,IF(UPPER(G32)=UPPER('Race Results'!E6),3,IF(UPPER(G32)=UPPER('Race Results'!F6),2,IF(UPPER(G32)=UPPER('Race Results'!G6),1,0))))))) | J32: =IF(I32="","",IF(UPPER(I32)=UPPER('Race Results'!B7),10,IF(UPPER(I32)=UPPER('Race Results'!C7),6,IF(UPPER(I32)=UPPER('Race Results'!D7),4,IF(UPPER(I32)=UPPER('Race Results'!E7),3,IF(UPPER(I32)=UPPER('Race Results'!F7),2,IF(UPPER(I32)=UPPER('Race Results'!G7),1,0))))))) | L32: =IF(K32="","",IF(UPPER(K32)=UPPER('Race Results'!B8),10,IF(UPPER(K32)=UPPER('Race Results'!C8),6,IF(UPPER(K32)=UPPER('Race Results'!D8),4,IF(UPPER(K32)=UPPER('Race Results'!E8),3,IF(UPPER(K32)=UPPER('Race Results'!F8),2,IF(UPPER(K32)=UPPER('Race Results'!G8),1,0))))))) | M32: =IF(COUNTA(D32,F32,H32,J32,L32)=0,"",SUM(D32,F32,H32,J32,L32)) -> 0
A33: 30 | D33: =IF(C33="","",IF(UPPER(C33)=UPPER('Race Results'!B4),10,IF(UPPER(C33)=UPPER('Race Results'!C4),6,IF(UPPER(C33)=UPPER('Race Results'!D4),4,IF(UPPER(C33)=UPPER('Race Results'!E4),3,IF(UPPER(C33)=UPPER('Race Results'!F4),2,IF(UPPER(C33)=UPPER('Race Results'!G4),1,0))))))) | F33: =IF(E33="","",IF(UPPER(E33)=UPPER('Race Results'!B5),10,IF(UPPER(E33)=UPPER('Race Results'!C5),6,IF(UPPER(E33)=UPPER('Race Results'!D5),4,IF(UPPER(E33)=UPPER('Race Results'!E5),3,IF(UPPER(E33)=UPPER('Race Results'!F5),2,IF(UPPER(E33)=UPPER('Race Results'!G5),1,0))))))) | H33: =IF(G33="","",IF(UPPER(G33)=UPPER('Race Results'!B6),10,IF(UPPER(G33)=UPPER('Race Results'!C6),6,IF(UPPER(G33)=UPPER('Race Results'!D6),4,IF(UPPER(G33)=UPPER('Race Results'!E6),3,IF(UPPER(G33)=UPPER('Race Results'!F6),2,IF(UPPER(G33)=UPPER('Race Results'!G6),1,0))))))) | J33: =IF(I33="","",IF(UPPER(I33)=UPPER('Race Results'!B7),10,IF(UPPER(I33)=UPPER('Race Results'!C7),6,IF(UPPER(I33)=UPPER('Race Results'!D7),4,IF(UPPER(I33)=UPPER('Race Results'!E7),3,IF(UPPER(I33)=UPPER('Race Results'!F7),2,IF(UPPER(I33)=UPPER('Race Results'!G7),1,0))))))) | L33: =IF(K33="","",IF(UPPER(K33)=UPPER('Race Results'!B8),10,IF(UPPER(K33)=UPPER('Race Results'!C8),6,IF(UPPER(K33)=UPPER('Race Results'!D8),4,IF(UPPER(K33)=UPPER('Race Results'!E8),3,IF(UPPER(K33)=UPPER('Race Results'!F8),2,IF(UPPER(K33)=UPPER('Race Results'!G8),1,0))))))) | M33: =IF(COUNTA(D33,F33,H33,J33,L33)=0,"",SUM(D33,F33,H33,J33,L33)) -> 0

Sheet Leaderboard
A1: LEADERBOARD
A2: Rank | B2: Guest | C2: Total Points | D2: Winners
A3: 1 | B3: =IFERROR(INDEX('Picks & Scores'!$B$4:$B$33,MATCH(LARGE('Picks & Scores'!$M$4:$M$33,1),'Picks & Scores'!$M$4:$M$33,0)),"") -> Emily Sardo | C3: =IFERROR(LARGE('Picks & Scores'!$M$4:$M$33,1),"") -> 30 | D3: =IFERROR(COUNTIF(OFFSET('Picks & Scores'!$D$4:$L$33,MATCH(C3,'Picks & Scores'!$M$4:$M$33,0)-1,0,1,11),10),"") -> 3
A4: 2 | B4: =IFERROR(INDEX('Picks & Scores'!$B$4:$B$33,MATCH(LARGE('Picks & Scores'!$M$4:$M$33,2),'Picks & Scores'!$M$4:$M$33,0)),"") -> Robb Topp | C4: =IFERROR(LARGE('Picks & Scores'!$M$4:$M$33,2),"") -> 26 | D4: =IFERROR(COUNTIF(OFFSET('Picks & Scores'!$D$4:$L$33,MATCH(C4,'Picks & Scores'!$M$4:$M$33,0)-1,0,1,11),10),"") -> 2
A5: 3 | B5: =IFERROR(INDEX('Picks & Scores'!$B$4:$B$33,MATCH(LARGE('Picks & Scores'!$M$4:$M$33,3),'Picks & Scores'!$M$4:$M$33,0)),"") -> Marianne Chardon | C5: =IFERROR(LARGE('Picks & Scores'!$M$4:$M$33,3),"") -> 22 | D5: =IFERROR(COUNTIF(OFFSET('Picks & Scores'!$D$4:$L$33,MATCH(C5,'Picks & Scores'!$M$4:$M$33,0)-1,0,1,11),10),"") -> 1
A6: 4 | B6: =IFERROR(INDEX('Picks & Scores'!$B$4:$B$33,MATCH(LARGE('Picks & Scores'!$M$4:$M$33,4),'Picks & Scores'!$M$4:$M$33,0)),"") -> Marianne Chardon | C6: =IFERROR(LARGE('Picks & Scores'!$M$4:$M$33,4),"") -> 22 | D6: =IFERROR(COUNTIF(OFFSET('Picks & Scores'!$D$4:$L$33,MATCH(C6,'Picks & Scores'!$M$4:$M$33,0)-1,0,1,11),10),"") -> 1
A7: 5 | B7: =IFERROR(INDEX('Picks & Scores'!$B$4:$B$33,MATCH(LARGE('Picks & Scores'!$M$4:$M$33,5),'Picks & Scores'!$M$4:$M$33,0)),"") -> Vahi Crowley | C7: =IFERROR(LARGE('Picks & Scores'!$M$4:$M$33,5),"") -> 20 | D7: =IFERROR(COUNTIF(OFFSET('Picks & Scores'!$D$4:$L$33,MATCH(C7,'Picks & Scores'!$M$4:$M$33,0)-1,0,1,11),10),"") -> 1
A8: 6 | B8: =IFERROR(INDEX('Picks & Scores'!$B$4:$B$33,MATCH(LARGE('Picks & Scores'!$M$4:$M$33,6),'Picks & Scores'!$M$4:$M$33,0)),"") -> Vahi Crowley | C8: =IFERROR(LARGE('Picks & Scores'!$M$4:$M$33,6),"") -> 20 | D8: =IFERROR(COUNTIF(OFFSET('Picks & Scores'!$D$4:$L$33,MATCH(C8,'Picks & Scores'!$M$4:$M$33,0)-1,0,1,11),10),"") -> 1
A9: 7 | B9: =IFERROR(INDEX('Picks & Scores'!$B$4:$B$33,MATCH(LARGE('Picks & Scores'!$M$4:$M$33,7),'Picks & Scores'!$M$4:$M$33,0)),"") -> Vahi Crowley | C9: =IFERROR(LARGE('Picks & Scores'!$M$4:$M$33,7),"") -> 20 | D9: =IFERROR(COUNTIF(OFFSET('Picks & Scores'!$D$4:$L$33,MATCH(C9,'Picks & Scores'!$M$4:$M$33,0)-1,0,1,11),10),"") -> 1
A10: 8 | B10: =IFERROR(INDEX('Picks & Scores'!$B$4:$B$33,MATCH(LARGE('Picks & Scores'!$M$4:$M$33,8),'Picks & Scores'!$M$4:$M$33,0)),"") -> Anthony Burke | C10: =IFERROR(LARGE('Picks & Scores'!$M$4:$M$33,8),"") -> 19 | D10: =IFERROR(COUNTIF(OFFSET('Picks & Scores'!$D$4:$L$33,MATCH(C10,'Picks & Scores'!$M$4:$M$33,0)-1,0,1,11),10),"") -> 1
A11: 9 | B11: =IFERROR(INDEX('Picks & Scores'!$B$4:$B$33,MATCH(LARGE('Picks & Scores'!$M$4:$M$33,9),'Picks & Scores'!$M$4:$M$33,0)),"") -> Bryan White | C11: =IFERROR(LARGE('Picks & Scores'!$M$4:$M$33,9),"") -> 17 | D11: =IFERROR(COUNTIF(OFFSET('Picks & Scores'!$D$4:$L$33,MATCH(C11,'Picks & Scores'!$M$4:$M$33,0)-1,0,1,11),10),"") -> 1
A12: 10 | B12: =IFERROR(INDEX('Picks & Scores'!$B$4:$B$33,MATCH(LARGE('Picks & Scores'!$M$4:$M$33,10),'Picks & Scores'!$M$4:$M$33,0)),"") -> Bryan White | C12: =IFERROR(LARGE('Picks & Scores'!$M$4:$M$33,10),"") -> 17 | D12: =IFERROR(COUNTIF(OFFSET('Picks & Scores'!$D$4:$L$33,MATCH(C12,'Picks & Scores'!$M$4:$M$33,0)-1,0,1,11),10),"") -> 1
A13: 11 | B13: =IFERROR(INDEX('Picks & Scores'!$B$4:$B$33,MATCH(LARGE('Picks & Scores'!$M$4:$M$33,11),'Picks & Scores'!$M$4:$M$33,0)),"") -> Stephen Hughes | C13: =IFERROR(LARGE('Picks & Scores'!$M$4:$M$33,11),"") -> 16 | D13: =IFERROR(COUNTIF(OFFSET('Picks & Scores'!$D$4:$L$33,MATCH(C13,'Picks & Scores'!$M$4:$M$33,0)-1,0,1,11),10),"") -> 1
A14: 12 | B14: =IFERROR(INDEX('Picks & Scores'!$B$4:$B$33,MATCH(LARGE('Picks & Scores'!$M$4:$M$33,12),'Picks & Scores'!$M$4:$M$33,0)),"") -> David Owens | C14: =IFERROR(LARGE('Picks & Scores'!$M$4:$M$33,12),"") -> 14 | D14: =IFERROR(COUNTIF(OFFSET('Picks & Scores'!$D$4:$L$33,MATCH(C14,'Picks & Scores'!$M$4:$M$33,0)-1,0,1,11),10),"") -> 1
A15: 13 | B15: =IFERROR(INDEX('Picks & Scores'!$B$4:$B$33,MATCH(LARGE('Picks & Scores'!$M$4:$M$33,13),'Picks & Scores'!$M$4:$M$33,0)),"") -> David Owens | C15: =IFERROR(LARGE('Picks & Scores'!$M$4:$M$33,13),"") -> 14 | D15: =IFERROR(COUNTIF(OFFSET('Picks & Scores'!$D$4:$L$33,MATCH(C15,'Picks & Scores'!$M$4:$M$33,0)-1,0,1,11),10),"") -> 1
A16: 14 | B16: =IFERROR(INDEX('Picks & Scores'!$B$4:$B$33,MATCH(LARGE('Picks & Scores'!$M$4:$M$33,14),'Picks & Scores'!$M$4:$M$33,0)),"") -> David Owens | C16: =IFERROR(LARGE('Picks & Scores'!$M$4:$M$33,14),"") -> 14 | D16: =IFERROR(COUNTIF(OFFSET('Picks & Scores'!$D$4:$L$33,MATCH(C16,'Picks & Scores'!$M$4:$M$33,0)-1,0,1,11),10),"") -> 1
A17: 15 | B17: =IFERROR(INDEX('Picks & Scores'!$B$4:$B$33,MATCH(LARGE('Picks & Scores'!$M$4:$M$33,15),'Picks & Scores'!$M$4:$M$33,0)),"") -> Sean Horan | C17: =IFERROR(LARGE('Picks & Scores'!$M$4:$M$33,15),"") -> 13 | D17: =IFERROR(COUNTIF(OFFSET('Picks & Scores'!$D$4:$L$33,MATCH(C17,'Picks & Scores'!$M$4:$M$33,0)-1,0,1,11),10),"") -> 1
A18: 16 | B18: =IFERROR(INDEX('Picks & Scores'!$B$4:$B$33,MATCH(LARGE('Picks & Scores'!$M$4:$M$33,16),'Picks & Scores'!$M$4:$M$33,0)),"") -> Darren Gill | C18: =IFERROR(LARGE('Picks & Scores'!$M$4:$M$33,16),"") -> 12 | D18: =IFERROR(COUNTIF(OFFSET('Picks & Scores'!$D$4:$L$33,MATCH(C18,'Picks & Scores'!$M$4:$M$33,0)-1,0,1,11),10),"") -> 0
A19: 17 | B19: =IFERROR(INDEX('Picks & Scores'!$B$4:$B$33,MATCH(LARGE('Picks & Scores'!$M$4:$M$33,17),'Picks & Scores'!$M$4:$M$33,0)),"") -> Jack Webb | C19: =IFERROR(LARGE('Picks & Scores'!$M$4:$M$33,17),"") -> 10 | D19: =IFERROR(COUNTIF(OFFSET('Picks & Scores'!$D$4:$L$33,MATCH(C19,'Picks & Scores'!$M$4:$M$33,0)-1,0,1,11),10),"") -> 2
A20: 18 | B20: =IFERROR(INDEX('Picks & Scores'!$B$4:$B$33,MATCH(LARGE('Picks & Scores'!$M$4:$M$33,18),'Picks & Scores'!$M$4:$M$33,0)),"") -> Ronan Keohane | C20: =IFERROR(LARGE('Picks & Scores'!$M$4:$M$33,18),"") -> 8 | D20: =IFERROR(COUNTIF(OFFSET('Picks & Scores'!$D$4:$L$33,MATCH(C20,'Picks & Scores'!$M$4:$M$33,0)-1,0,1,11),10),"") -> 0
A21: 19 | B21: =IFERROR(INDEX('Picks & Scores'!$B$4:$B$33,MATCH(LARGE('Picks & Scores'!$M$4:$M$33,19),'Picks & Scores'!$M$4:$M$33,0)),"") -> Ronan Keohane | C21: =IFERROR(LARGE('Picks & Scores'!$M$4:$M$33,19),"") -> 8 | D21: =IFERROR(COUNTIF(OFFSET('Picks & Scores'!$D$4:$L$33,MATCH(C21,'Picks & Scores'!$M$4:$M$33,0)-1,0,1,11),10),"") -> 0
A22: 20 | B22: =IFERROR(INDEX('Picks & Scores'!$B$4:$B$33,MATCH(LARGE('Picks & Scores'!$M$4:$M$33,20),'Picks & Scores'!$M$4:$M$33,0)),"") -> Lynn Forsyth | C22: =IFERROR(LARGE('Picks & Scores'!$M$4:$M$33,20),"") -> 7 | D22: =IFERROR(COUNTIF(OFFSET('Picks & Scores'!$D$4:$L$33,MATCH(C22,'Picks & Scores'!$M$4:$M$33,0)-1,0,1,11),10),"") -> 0
A23: 21 | B23: =IFERROR(INDEX('Picks & Scores'!$B$4:$B$33,MATCH(LARGE('Picks & Scores'!$M$4:$M$33,21),'Picks & Scores'!$M$4:$M$33,0)),"") -> Lynn Forsyth | C23: =IFERROR(LARGE('Picks & Scores'!$M$4:$M$33,21),"") -> 7 | D23: =IFERROR(COUNTIF(OFFSET('Picks & Scores'!$D$4:$L$33,MATCH(C23,'Picks & Scores'!$M$4:$M$33,0)-1,0,1,11),10),"") -> 0
A24: 22 | B24: =IFERROR(INDEX('Picks & Scores'!$B$4:$B$33,MATCH(LARGE('Picks & Scores'!$M$4:$M$33,22),'Picks & Scores'!$M$4:$M$33,0)),"") -> Ryan Crowley | C24: =IFERROR(LARGE('Picks & Scores'!$M$4:$M$33,22),"") -> 6 | D24: =IFERROR(COUNTIF(OFFSET('Picks & Scores'!$D$4:$L$33,MATCH(C24,'Picks & Scores'!$M$4:$M$33,0)-1,0,1,11),10),"") -> 0
A25: 23 | B25: =IFERROR(INDEX('Picks & Scores'!$B$4:$B$33,MATCH(LARGE('Picks & Scores'!$M$4:$M$33,23),'Picks & Scores'!$M$4:$M$33,0)),"") -> Ryan Crowley | C25: =IFERROR(LARGE('Picks & Scores'!$M$4:$M$33,23),"") -> 6 | D25: =IFERROR(COUNTIF(OFFSET('Picks & Scores'!$D$4:$L$33,MATCH(C25,'Picks & Scores'!$M$4:$M$33,0)-1,0,1,11),10),"") -> 0
A26: 24 | B26: =IFERROR(INDEX('Picks & Scores'!$B$4:$B$33,MATCH(LARGE('Picks & Scores'!$M$4:$M$33,24),'Picks & Scores'!$M$4:$M$33,0)),"") -> Ryan Crowley | C26: =IFERROR(LARGE('Picks & Scores'!$M$4:$M$33,24),"") -> 6 | D26: =IFERROR(COUNTIF(OFFSET('Picks & Scores'!$D$4:$L$33,MATCH(C26,'Picks & Scores'!$M$4:$M$33,0)-1,0,1,11),10),"") -> 0
A27: 25 | B27: =IFERROR(INDEX('Picks & Scores'!$B$4:$B$33,MATCH(LARGE('Picks & Scores'!$M$4:$M$33,25),'Picks & Scores'!$M$4:$M$33,0)),"") -> Denise White | C27: =IFERROR(LARGE('Picks & Scores'!$M$4:$M$33,25),"") -> 4 | D27: =IFERROR(COUNTIF(OFFSET('Picks & Scores'!$D$4:$L$33,MATCH(C27,'Picks & Scores'!$M$4:$M$33,0)-1,0,1,11),10),"") -> 0
